[2024-06-17T12:29:46.613+0000] {local_task_job_runner.py:120} INFO - ::group::Pre task execution logs
[2024-06-17T12:29:46.644+0000] {taskinstance.py:2076} INFO - Dependencies all met for dep_context=non-requeueable deps ti=<TaskInstance: etl_ecomerc_pipeline.test_db scheduled__2024-06-16T00:00:00+00:00 [queued]>
[2024-06-17T12:29:46.653+0000] {taskinstance.py:2076} INFO - Dependencies all met for dep_context=requeueable deps ti=<TaskInstance: etl_ecomerc_pipeline.test_db scheduled__2024-06-16T00:00:00+00:00 [queued]>
[2024-06-17T12:29:46.654+0000] {taskinstance.py:2306} INFO - Starting attempt 1 of 1
[2024-06-17T12:29:46.667+0000] {taskinstance.py:2330} INFO - Executing <Task(SQLExecuteQueryOperator): test_db> on 2024-06-16 00:00:00+00:00
[2024-06-17T12:29:46.675+0000] {standard_task_runner.py:90} INFO - Running: ['***', 'tasks', 'run', 'etl_ecomerc_pipeline', 'test_db', 'scheduled__2024-06-16T00:00:00+00:00', '--job-id', '2', '--raw', '--subdir', 'DAGS_FOLDER/ecom_dag.py', '--cfg-path', '/tmp/tmpmfnqvwby']
[2024-06-17T12:29:46.677+0000] {standard_task_runner.py:91} INFO - Job 2: Subtask test_db
[2024-06-17T12:29:46.677+0000] {logging_mixin.py:188} WARNING - /home/***/.local/lib/python3.12/site-packages/***/task/task_runner/standard_task_runner.py:61 DeprecationWarning: This process (pid=184) is multi-threaded, use of fork() may lead to deadlocks in the child.
[2024-06-17T12:29:46.677+0000] {standard_task_runner.py:63} INFO - Started process 185 to run task
[2024-06-17T12:29:46.720+0000] {task_command.py:426} INFO - Running <TaskInstance: etl_ecomerc_pipeline.test_db scheduled__2024-06-16T00:00:00+00:00 [running]> on host 7a3e4b58d3b6
[2024-06-17T12:29:46.811+0000] {taskinstance.py:2648} INFO - Exporting env vars: AIRFLOW_CTX_DAG_OWNER='***' AIRFLOW_CTX_DAG_ID='etl_ecomerc_pipeline' AIRFLOW_CTX_TASK_ID='test_db' AIRFLOW_CTX_EXECUTION_DATE='2024-06-16T00:00:00+00:00' AIRFLOW_CTX_TRY_NUMBER='1' AIRFLOW_CTX_DAG_RUN_ID='scheduled__2024-06-16T00:00:00+00:00'
[2024-06-17T12:29:46.812+0000] {taskinstance.py:430} INFO - ::endgroup::
[2024-06-17T12:29:46.844+0000] {sql.py:276} INFO - Executing: 
            CREATE TABLE IF NOT EXISTS customers (
                customer_id INTEGER PRIMARY KEY,
                name VARCHAR(50) NOT NULL,
                customer_city VARCHAR(50)
            )
        
[2024-06-17T12:29:46.855+0000] {taskinstance.py:441} INFO - ::group::Post task execution logs
[2024-06-17T12:29:46.866+0000] {taskinstance.py:2905} ERROR - Task failed with exception
Traceback (most recent call last):
  File "/home/airflow/.local/lib/python3.12/site-packages/airflow/models/taskinstance.py", line 465, in _execute_task
    result = _execute_callable(context=context, **execute_callable_kwargs)
             ^^^^^^^^^^^^^^^^^^^^^^^^^^^^^^^^^^^^^^^^^^^^^^^^^^^^^^^^^^^^^
  File "/home/airflow/.local/lib/python3.12/site-packages/airflow/models/taskinstance.py", line 432, in _execute_callable
    return execute_callable(context=context, **execute_callable_kwargs)
           ^^^^^^^^^^^^^^^^^^^^^^^^^^^^^^^^^^^^^^^^^^^^^^^^^^^^^^^^^^^^
  File "/home/airflow/.local/lib/python3.12/site-packages/airflow/models/baseoperator.py", line 401, in wrapper
    return func(self, *args, **kwargs)
           ^^^^^^^^^^^^^^^^^^^^^^^^^^^
  File "/home/airflow/.local/lib/python3.12/site-packages/airflow/providers/common/sql/operators/sql.py", line 277, in execute
    hook = self.get_db_hook()
           ^^^^^^^^^^^^^^^^^^
  File "/home/airflow/.local/lib/python3.12/site-packages/airflow/providers/common/sql/operators/sql.py", line 188, in get_db_hook
    return self._hook
           ^^^^^^^^^^
  File "/usr/local/lib/python3.12/functools.py", line 995, in __get__
    val = self.func(instance)
          ^^^^^^^^^^^^^^^^^^^
  File "/home/airflow/.local/lib/python3.12/site-packages/airflow/providers/common/sql/operators/sql.py", line 150, in _hook
    conn = BaseHook.get_connection(conn_id)
           ^^^^^^^^^^^^^^^^^^^^^^^^^^^^^^^^
  File "/home/airflow/.local/lib/python3.12/site-packages/airflow/hooks/base.py", line 83, in get_connection
    conn = Connection.get_connection_from_secrets(conn_id)
           ^^^^^^^^^^^^^^^^^^^^^^^^^^^^^^^^^^^^^^^^^^^^^^^
  File "/home/airflow/.local/lib/python3.12/site-packages/airflow/models/connection.py", line 519, in get_connection_from_secrets
    raise AirflowNotFoundException(f"The conn_id `{conn_id}` isn't defined")
airflow.exceptions.AirflowNotFoundException: The conn_id `data_staging` isn't defined
[2024-06-17T12:29:46.871+0000] {taskinstance.py:1206} INFO - Marking task as FAILED. dag_id=etl_ecomerc_pipeline, task_id=test_db, run_id=scheduled__2024-06-16T00:00:00+00:00, execution_date=20240616T000000, start_date=20240617T122946, end_date=20240617T122946
[2024-06-17T12:29:46.884+0000] {standard_task_runner.py:110} ERROR - Failed to execute job 2 for task test_db (The conn_id `data_staging` isn't defined; 185)
[2024-06-17T12:29:46.891+0000] {local_task_job_runner.py:240} INFO - Task exited with return code 1
[2024-06-17T12:29:46.909+0000] {taskinstance.py:3503} INFO - 0 downstream tasks scheduled from follow-on schedule check
[2024-06-17T12:29:46.911+0000] {local_task_job_runner.py:222} INFO - ::endgroup::
